Workbook

Sheet Como usar
B1: Planilha de estudos · Patrícia de Miranda Oliveira
B2: Perito Legista PCERJ · 2h por dia · 26 semanas (02/11/2026 a 02/05/2027) · base: Edital nº 05/2021
B4: LEGENDA
B5: Células AMARELAS = você preenche. Todo o resto é calculado sozinho (não apague fórmulas).
B7: ROTINA DE USO
B8: 1. Todo dia, ao terminar o estudo (2 min): aba 'Registro diário' → uma linha por bloco (data, disciplina, código do tópico, atividade, minutos, questões, acertos).
B9: 2. Ao terminar a teoria de um tópico: aba 'Edital' → marque 'Teoria concluída = Sim' e a data do 1º estudo. As datas das revisões (24h, 7 e 30 dias) aparecem sozinhas.
B10: 3. Errou uma questão importante ou chutou e acertou: aba 'Caderno de erros' → uma linha. A data de revisão aparece sozinha.
B11: 4. Domingo, no bloco de revisão: abra 'Painel semanal' e leia a coluna ALERTA da semana. Faça as revisões marcadas como PENDENTE na aba 'Edital'. Marque o status da semana na aba 'Cronograma'.
B12: 5. Simulados: aba 'Simulados'. Teste físico: aba 'TAF'. Ao fim de cada dia: marque os blocos feitos na aba 'Checklist semanal'.
B14: ABAS
B15: Grade semanal — horários fixos de cada dia (07h–09h).
... B31: Dúvidas sobre COMO estudar (blocos, revisões, simulados, atrasos, checklists): consulte o GUIA DA ALUNA (PDF). Esta planilha e o guia são os únicos materiais da mentoria.

Sheet Grade semanal
A1: Grade semanal · 2h por dia (2 blocos de 1h)
A2: Cada bloco começa com 10 min de revisão de 24h da mesma matéria (escrever de memória 5 pontos do conteúdo anterior).
A4: Dia | B4: Bloco | C4: Horário | D4: Disciplina | E4: Atividade (Fase 1 · S1–S20) | F4: Atividade (Fase 2 · S21–S25)
A5: Segunda | B5: 1 | C5: 07:00–08:00 | D5: Medicina Legal | E5: Teoria do tópico da semana | F5: Correção do simulado / questões ML
A6: Segunda | B6: 2 | C6: 08:00–09:00 | D6: Medicina Legal | E6: Questões do tópico + resumo | F6: Questões ML
A7: Terça | B7: — | C7: — | D7: Plantão | E7: Sem estudo | F7: Sem estudo
A8: Quarta | B8: 1 | C8: 07:00–08:00 | D8: Português | E8: Teoria + questões | F8: Questões Português
A9: Quarta | B9: 2 | C9: 08:00–09:00 | D9: Direito | E9: Teoria resumida + lei seca | F9: Lei seca + questões Direito
A10: Quinta | B10: 1 | C10: 07:00–08:00 | D10: Medicina Legal | E10: Teoria (continuação) | F10: Teoria dirigida aos erros de ML
A11: Quinta | B11: 2 | C11: 08:00–09:00 | D11: Português | E11: Questões FGV | F11: Questões Português
A12: Sexta | B12: 1 | C12: 07:00–08:00 | D12: Medicina Legal | E12: Questões + flashcards | F12: Questões ML
A13: Sexta | B13: 2 | C13: 08:00–09:00 | D13: Direito | E13: Questões | F13: Questões Direito
A14: Sábado | B14: — | C14: — | D14: Plantão | E14: Sem estudo | F14: Sem estudo
A15: Domingo | B15: 1 | C15: 07:00–08:00 | D15: Português | E15: Interpretação de textos FGV | F15: Interpretação FGV (ou simulado 07h–12h)
A16: Domingo | B16: 2 | C16: 08:00–09:00 | D16: Revisão | E16: Revisão de 7 e 30 dias, caderno de erros, painel | F16: Revisão + painel (ou simulado)
A18: Total: Medicina Legal 4h · Português 3h · Direito 2h · Revisão 1h = 10h por semana.
A19: Semanas de simulado (S21, S23, S25): o domingo vira simulado de 100 questões das 07h às 12h (duração real da prova).
A20: Semanas de recuperação (S8 Natal, S15 Carnaval): carga reduzida (≈5h), só revisão e atrasos.

Sheet Cronograma
A1: Cronograma · 26 semanas
A2: Status e Observações são seus (amarelo). Os códigos (ML01, PT01, DI01…) são os mesmos da aba Edital.
A4: Semana | B4: Datas | C4: Fase | D4: Medicina Legal | E4: Português | F4: Direito | G4: Meta de questões | H4: Horas plan. | I4: Revisão 30 dias | J4: Simulado / TAF | K4: Resultado esperado | L4: Status | M4: Observações
A5: S1 | B5: 02/11–08/11/26 | C5: 1 · Base | D5: ML01 · Normas éticas x jurídicas; processo e provas; fatos duradouros e perícias; conceitos, história e divisões da Medicina Legal; perícias médicas e documentos médico-legais | E5: PT01 · Texto: gêneros (literário e não literário), tipologia (narrativo, descritivo, argumentativo), interpretação e organização interna | F5: DI01 · Constitucional: supremacia da Constituição; direitos e deveres individuais e coletivos (art. 5º, parte 1) | G5: 50 (ML 25 · Port 15 · Dir 10) | H5: 10 | I5: — | K5: Conhece os documentos médico-legais e o método de estudo está rodando
A6: S2 | B6: 09/11–15/11/26 | C6: 1 · Base | D6: ML02 · Identidade e identificação; métodos de identificação nos vivos e em cadáveres | E6: PT02 · Ortografia e acentuação gráfica | F6: DI02 · Constitucional: art. 5º, parte 2 (incl. remédios constitucionais) | G6: 50 (ML 25 · Port 15 · Dir 10) | H6: 10 | I6: — | K6: Tópicos da semana com teoria, questões e resumo feitos
A7: S3 | B7: 16/11–22/11/26 | C7: 1 · Base | D7: ML03 · Antropologia Forense: sexo, idade, estatura e ancestralidade | E7: PT03 · Morfologia I: substantivo, adjetivo, artigo, numeral e pronome | F7: DI03 · Constitucional: Administração Pública e servidores públicos civis (arts. 37–41) | G7: 50 (ML 25 · Port 15 · Dir 10) | H7: 10 | I7: — | K7: Fecha a parte de identificação e antropologia
A8: S4 | B8: 23/11–29/11/26 | C8: 1 · Base | D8: ML04 · Traumatologia I: conceitos de trauma e lesão; consequências jurídicas dos traumas; agentes mecânicos (contundentes, cortantes, perfurantes e mistos) | E8: PT04 · Morfologia II: verbo — flexão e emprego de tempos e modos | F8: DI04 · Constitucional: Poder Executivo (forma e sistema de governo, chefias); Segurança Pública na CF e na Constituição do RJ; Ordem social | G8: 50 (ML 25 · Port 15 · Dir 10) | H8: 10 | I8: — | J8: Teste físico (TAF) | K8: Fecha Constitucional na 1ª leitura
A9: S5 | B9: 30/11–06/12/26 | C9: 1 · Base | D9: ML05 · Traumatologia II: armas de fogo (agentes perfurocontundentes) | E9: PT05 · Advérbio, preposição e conjunção; processos de formação de palavras | F9: DI05 · Penal: fato típico; dolo e culpa; consumação e tentativa; crime impossível | G9: 50 (ML 25 · Port 15 · Dir 10) | H9: 10 | I9: S1 | K9: Tópicos da semana com teoria, questões e resumo feitos
A10: S6 | B10: 07/12–13/12/26 | C10: 1 · Base | D10: ML06 · Traumatologia III: agentes físicos, químicos e outros vulnerantes; idade da lesão e reação vital | E10: PT06 · Semântica: sentido e emprego dos vocábulos; campos semânticos | F10: DI06 · Penal: inimputabilidade penal; medidas de segurança; crimes contra a pessoa (parte 1) | G10: 50 (ML 25 · Port 15 · Dir 10) | H10: 10 | I10: S2 | K10: Fecha Traumatologia
A11: S7 | B11: 14/12–20/12/26 | C11: 1 · Base | D11: ML07 · Asfixiologia I: conceito e classificação etiológica; sufocação direta e indireta; enforcamento, estrangulamento e esganadura | E11: PT07 · Sintaxe I: frase, oração e período; termos da oração | F11: DI07 · Penal: crimes contra a pessoa (parte 2); crimes contra a liberdade individual | G11: 50 (ML 25 · Port 15 · Dir 10) | H11: 10 | I11: S3 | K11: Fecha Penal parte geral
A12: S8 | B12: 21/12–27/12/26 | C12: 1 · Base | D12: Semana de recuperação (Natal): carga reduzida (≈5h). Sem conteúdo novo: pôr atrasos em dia, revisão de 30 dias de S1–S7, flashcards e caderno de erros. | G12: 30 (livre (revisão)) | H12: 5 | I12: — | J12: Teste físico (TAF) | K12: Tópicos da semana com teoria, questões e resumo feitos
A13: S9 | B13: 28/12–03/01/27 | C13: 1 · Base | D13: ML08 · Asfixiologia II: confinamento, soterramento e afogamento | E13: PT08 · Sintaxe II: processos de coordenação e subordinação | F13: DI08 · Penal: crimes contra a dignidade sexual; crimes contra a administração pública | G13: 70 (ML 35 · Port 20 · Dir 15) | H13: 10 | I13: S5 | K13: Fecha Asfixiologia
A14: S10 | B14: 04/01–10/01/27 | C14: 1 · Base | D14: ML09 · Tanatologia I: diagnóstico da morte e consequências jurídicas; conceito moderno de morte e doação de órgãos; causa jurídica da morte (natural, violenta, suspeita, súbita) | E14: PT09 · Concordância nominal e verbal | F14: DI09 · Proc. Penal: garantias constitucionais; inquérito policial; polícia judiciária; diligências; auto de resistência; algemas (Lei 13.434/2017 e LEP) | G14: 70 (ML 35 · Port 20 · Dir 15) | H14: 10 | I14: S6 | K14: Tópicos da semana com teoria, questões e resumo feitos
A15: S11 | B15: 11/01–17/01/27 | C15: 1 · Base | D15: ML10 · Tanatologia II: cronotanatognose; fenômenos cadavéricos e estimativa do tempo de morte | E15: PT10 · Transitividade e regência de nomes e verbos | F15: DI10 · Proc. Penal: prova pericial; corpo de delito; cadeia de custódia (Lei 13.964/2019); identificação criminal e perfil genético (Leis 12.037/2009 e 12.654/2012) | G15: 70 (ML 35 · Port 20 · Dir 15) | H15: 10 | I15: S7 | K15: Proc. Penal completo; linha do tempo cadavérica sem consulta
A16: S12 | B16: 18/01–24/01/27 | C16: 1 · Base | D16: ML11 · Tanatologia III: declaração de óbito; necessidade da necrópsia médico-legal. Infortunística: acidentes do trabalho e doenças profissionais | E16: PT11 · Emprego do sinal indicativo de crase | F16: DI11 · Leis especiais: Tortura (9.455/1997); Abuso de autoridade (13.869/2019); Racismo (7.716/1989) | G16: 70 (ML 35 · Port 20 · Dir 15) | H16: 10 | I16: S9 | J16: Teste físico (TAF) | K16: Tópicos da semana com teoria, questões e resumo feitos
A17: S13 | B17: 25/01–31/01/27 | C17: 1 · Base | D17: ML12 · Toxicologia I: cáusticos e venenos; intoxicações exógenas (acidentais, suicidas, criminosas); necrópsia na suspeita de intoxicação; coleta de material toxicológico | E17: PT12 · Padrões gerais de colocação pronominal | F17: DI12 · Leis especiais: Drogas (11.343/2006); ECA (8.069/1990) | G17: 70 (ML 35 · Port 20 · Dir 15) | H17: 10 | I17: S10 | J17: Mini-simulado diagnóstico (40 q.) no domingo | K17: Primeira medida real de desempenho (diagnóstico)
A18: S14 | B18: 01/02–07/02/27 | C18: 1 · Base | D18: ML13 · Toxicologia II: estudo médico-legal do abuso de álcool e de outras drogas | E18: PT13 · Pontuação | F18: DI13 · Leis especiais: Maria da Penha (11.340/2006) e Sinal Vermelho (13.505/2017, 13.894/2019, 14.188/2021); atendimento policial e pericial especializado; Estatuto do Idoso (10.741/2003); Estatuto da PcD (13.146/2015) | G18: 70 (ML 35 · Port 20 · Dir 15) | H18: 10 | I18: S11 | K18: Fecha Toxicologia e as leis especiais
A19: S15 | B19: 08/02–14/02/27 | C19: 1 · Base | D19: Semana de recuperação (Carnaval): carga reduzida (≈5h). Sem conteúdo novo: pôr atrasos em dia, revisão de 30 dias de S9–S14, flashcards e caderno de erros. | G19: 30 (livre (revisão)) | H19: 5 | I19: — | K19: Tópicos da semana com teoria, questões e resumo feitos
A20: S16 | B20: 15/02–21/02/27 | C20: 1 · Base | D20: ML14 · Sexologia I: crimes contra a liberdade sexual; conjunção carnal e atos libidinosos; manchas de sêmen; formas de violência nos atos libidinosos | E20: PT14 · Mecanismos de coesão textual | F20: DI14 · Administrativo: conceito de Administração Pública; organização administrativa; ato administrativo | G20: 70 (ML 35 · Port 20 · Dir 15) | H20: 10 | I20: S12 | J20: Teste físico (TAF) | K20: Tópicos da semana com teoria, questões e resumo feitos
A21: S17 | B21: 22/02–28/02/27 | C21: 1 · Base | D21: ML15 · Sexologia II: gravidez, parto recente e puerpério; aborto; infanticídio | E21: PT15 · Reescrita de frases I: substituição e deslocamento | F21: DI15 · Administrativo: poderes (hierárquico, regulamentar, disciplinar, de polícia); limites do poder de polícia; uso e abuso de poder; agentes públicos; cargo, emprego e função; responsabilidade civil do Estado | G21: 70 (ML 35 · Port 20 · Dir 15) | H21: 10 | I21: S13 | K21: Tópicos da semana com teoria, questões e resumo feitos
A22: S18 | B22: 01/03–07/03/27 | C22: 1 · Base | D22: ML16 · Sexologia III: maus-tratos a vulneráveis; contágio venéreo; casamento; filiação por exame de DNA | E22: PT16 · Reescrita de frases II: paralelismo; variação linguística e norma culta | F22: DI16 · Estatuto dos Funcionários Públicos Civis do RJ (DL 220/1975) e Regulamento (Dec. 2.479/1979) | G22: 70 (ML 35 · Port 20 · Dir 15) | H22: 10 | I22: S14 | K22: Fecha Sexologia e reescrita
A23: S19 | B23: 08/03–14/03/27 | C23: 1 · Base | D23: ML17 · Psiquiatria Forense: imputabilidade penal e capacidade civil | E23: Bateria de interpretação de textos FGV | F23: DI17 · Estatuto dos Policiais Civis do RJ (DL 218/1975) e Regulamento (Dec. 3.044/1979) | G23: 70 (ML 35 · Port 20 · Dir 15) | H23: 10 | I23: S16 | K23: Fecha os estatutos do RJ
A24: S20 | B24: 15/03–21/03/27 | C24: 1 · Base | D24: ML18 · Diceologia e Deontologia médicas | E24: Revisão de gramática pelo caderno de erros | F24: Questões mistas de Direito (todas as áreas) | G24: 70 (ML 35 · Port 20 · Dir 15) | H24: 10 | I24: S17 | J24: Teste físico (TAF) | K24: 1ª leitura de TODO o edital concluída
A25: S21 | B25: 22/03–28/03/27 | C25: 2 · Questões e simulados | D25: Questões: Traumatologia e Asfixiologia (ML04–ML08) | E25: Questões: interpretação + concordância e regência | F25: Questões: Constitucional + Penal (DI01–DI08) | G25: 120 (ML 60 · Port 35 · Dir 25) | H25: 13 | I25: S18 | J25: Simulado 1 (100 q.) — domingo 07h–12h | K25: Acima de 60% em cada módulo no Simulado 1
A26: S22 | B26: 29/03–04/04/27 | C26: 2 · Questões e simulados | D26: Questões: Tanatologia, Infortunística e Toxicologia (ML09–ML13) | E26: Questões: sintaxe, pontuação e crase | F26: Questões: Processo Penal + leis especiais (DI09–DI13) | G26: 120 (ML 60 · Port 35 · Dir 25) | H26: 10 | I26: S19 | K26: Tópicos da semana com teoria, questões e resumo feitos
A27: S23 | B27: 05/04–11/04/27 | C27: 2 · Questões e simulados | D27: Questões: Sexologia, DNA e Psiquiatria (ML14–ML17) | E27: Questões: coesão e reescrita | F27: Questões: Administrativo + estatutos RJ (DI14–DI17) | G27: 120 (ML 60 · Port 35 · Dir 25) | H27: 13 | I27: S20 | J27: Simulado 2 (100 q.) — domingo 07h–12h | K27: Acima de 65% no geral
A28: S24 | B28: 12/04–18/04/27 | C28: 2 · Questões e simulados | D28: Questões: Identificação, Antropologia, perícias e Deontologia (ML01–ML03, ML18) + tópicos com mais erros | E28: Questões mistas FGV | F28: Questões mistas + lei seca dos tópicos com mais erros | G28: 120 (ML 60 · Port 35 · Dir 25) | H28: 10 | I28: — | J28: Teste físico (TAF) | K28: Lista final de pontos fracos atacada
A29: S25 | B29: 19/04–25/04/27 | C29: 2 · Questões e simulados | D29: Revisão final por resumos e flashcards (todo o conteúdo) | E29: Caderno de erros de Português | F29: Lei seca: trechos grifados | G29: 120 (ML 60 · Port 35 · Dir 25) | H29: 13 | I29: — | J29: Simulado 3 (100 q.) — domingo 07h–12h | K29: Acima de 70% no geral e de 60% em cada módulo
A30: S26 | B30: 26/04–02/05/27 | C30: 3 · Reta final | D30: Semana pré-prova: nada de conteúdo novo; mini-simulado de 30 q. até quarta; logística da prova; descanso na véspera. | G30: 40 (mini-simulado 30 + revisão) | H30: 6 | I30: — | K30: Chega à prova descansada
A32: Total de horas planejadas: | H32: =SUM(H5:H30) -> 255

Sheet Checklist semanal
A1: Checklist semanal · marque ✓ em cada bloco concluído
A2: Bloco 1 = 07h–08h · Bloco 2 = 08h–09h. Terça e sábado são plantão. Na semana de simulado, os 2 blocos de domingo = simulado.
A4: Semana | B4: Datas | C4: Seg B1 | D4: Seg B2 | E4: Qua B1 | F4: Qua B2 | G4: Qui B1 | H4: Qui B2 | I4: Sex B1 | J4: Sex B2 | K4: Dom B1 | L4: Dom B2 | M4: Blocos plan. | N4: Blocos feitos | O4: % feito | P4: Dias com flashcards (0–5) | Q4: Ritual de domingo feito? | R4: Print enviado à mentora?
A5: S1 | B5: 02/11–08/11/26 | M5: 10 | N5: =COUNTIF(C5:L5,"✓") -> 0 | O5: =IF(N5=0,"",N5/M5)
A6: S2 | B6: 09/11–15/11/26 | M6: 10 | N6: =COUNTIF(C6:L6,"✓") -> 0 | O6: =IF(N6=0,"",N6/M6)
A7: S3 | B7: 16/11–22/11/26 | M7: 10 | N7: =COUNTIF(C7:L7,"✓") -> 0 | O7: =IF(N7=0,"",N7/M7)
A8: S4 | B8: 23/11–29/11/26 | M8: 10 | N8: =COUNTIF(C8:L8,"✓") -> 0 | O8: =IF(N8=0,"",N8/M8)
A9: S5 | B9: 30/11–06/12/26 | M9: 10 | N9: =COUNTIF(C9:L9,"✓") -> 0 | O9: =IF(N9=0,"",N9/M9)
A10: S6 | B10: 07/12–13/12/26 | M10: 10 | N10: =COUNTIF(C10:L10,"✓") -> 0 | O10: =IF(N10=0,"",N10/M10)
A11: S7 | B11: 14/12–20/12/26 | M11: 10 | N11: =COUNTIF(C11:L11,"✓") -> 0 | O11: =IF(N11=0,"",N11/M11)
A12: S8 | B12: 21/12–27/12/26 | M12: 5 | N12: =COUNTIF(C12:L12,"✓") -> 0 | O12: =IF(N12=0,"",N12/M12)
A13: S9 | B13: 28/12–03/01/27 | M13: 10 | N13: =COUNTIF(C13:L13,"✓") -> 0 | O13: =IF(N13=0,"",N13/M13)
A14: S10 | B14: 04/01–10/01/27 | M14: 10 | N14: =COUNTIF(C14:L14,"✓") -> 0 | O14: =IF(N14=0,"",N14/M14)
A15: S11 | B15: 11/01–17/01/27 | M15: 10 | N15: =COUNTIF(C15:L15,"✓") -> 0 | O15: =IF(N15=0,"",N15/M15)
A16: S12 | B16: 18/01–24/01/27 | M16: 10 | N16: =COUNTIF(C16:L16,"✓") -> 0 | O16: =IF(N16=0,"",N16/M16)
... A30: S26 | B30: 26/04–02/05/27 | M30: 6 | N30: =COUNTIF(C30:L30,"✓") -> 0 | O30: =IF(N30=0,"",N30/M30)

Sheet Edital
A1: Checklist do edital · 51 tópicos
A2: Preencha só as colunas amarelas. Revisões vencidas aparecem como PENDENTE.
A3: Edital concluído | B3: =COUNTIF(O7:O57,"Concluído")/51 -> 0 | C3: ML | D3: =COUNTIFS(A7:A57,"Medicina Legal",O7:O57,"Concluído")/COUNTIF(A7:A57,"Medicina Legal") -> 0 | E3: Port. | F3: =COUNTIFS(A7:A57,"Português",O7:O57,"Concluído")/COUNTIF(A7:A57,"Português") -> 0 | G3: Dir. | H3: =COUNTIFS(A7:A57,"Direito",O7:O57,"Concluído")/COUNTIF(A7:A57,"Direito") -> 0
A4: Revisões pendentes | B4: =COUNTIF(P7:P57,"PENDENTE") -> 0 | C4: Tópicos atrasados | E4: =COUNTIF(O7:O57,"Atrasado") -> 0
A6: Disciplina | B6: Código | C6: Tópico do edital | D6: Semana prevista | E6: Teoria concluída? | F6: Data do 1º estudo | G6: Rev. 24h | H6: Rev. 7 dias | I6: Rev. 30 dias | J6: Rev. 7d feita? | K6: Rev. 30d feita? | L6: Questões | M6: Acertos | N6: % acerto | O6: Status | P6: Revisão
A7: Medicina Legal | B7: ML01 | C7: Normas éticas x jurídicas; processo e provas; fatos duradouros e perícias; conceitos, história e divisões da Medicina Legal; perícias médicas e documentos médico-legais | D7: 1 | G7: =IF(F7="","",F7+1) | H7: =IF(F7="","",F7+7) | I7: =IF(F7="","",F7+30) | L7: =SUMIFS('Registro diário'!$G$6:$G$504,'Registro diário'!$D$6:$D$504,B7) -> 0 | M7: =SUMIFS('Registro diário'!$H$6:$H$504,'Registro diário'!$D$6:$D$504,B7) -> 0 | N7: =IF(L7=0,"",M7/L7) | O7: =IF(AND(E7="Sim",L7>0),"Concluído",IF(OR(E7="Sim",L7>0),"Em andamento",IF(TODAY()>DATE(2026,11,2)+7*D7-1,"Atrasado","A fazer"))) -> A fazer | P7: =IF(F7="","",IF(OR(AND(J7<>"Sim",TODAY()>=H7),AND(K7<>"Sim",TODAY()>=I7)),"PENDENTE","ok"))
A8: Medicina Legal | B8: ML02 | C8: Identidade e identificação; métodos de identificação nos vivos e em cadáveres | D8: 2 | G8: =IF(F8="","",F8+1) | H8: =IF(F8="","",F8+7) | I8: =IF(F8="","",F8+30) | L8: =SUMIFS('Registro diário'!$G$6:$G$504,'Registro diário'!$D$6:$D$504,B8) -> 0 | M8: =SUMIFS('Registro diário'!$H$6:$H$504,'Registro diário'!$D$6:$D$504,B8) -> 0 | N8: =IF(L8=0,"",M8/L8) | O8: =IF(AND(E8="Sim",L8>0),"Concluído",IF(OR(E8="Sim",L8>0),"Em andamento",IF(TODAY()>DATE(2026,11,2)+7*D8-1,"Atrasado","A fazer"))) -> A fazer | P8: =IF(F8="","",IF(OR(AND(J8<>"Sim",TODAY()>=H8),AND(K8<>"Sim",TODAY()>=I8)),"PENDENTE","ok"))
A9: Medicina Legal | B9: ML03 | C9: Antropologia Forense: sexo, idade, estatura e ancestralidade | D9: 3 | G9: =IF(F9="","",F9+1) | H9: =IF(F9="","",F9+7) | I9: =IF(F9="","",F9+30) | L9: =SUMIFS('Registro diário'!$G$6:$G$504,'Registro diário'!$D$6:$D$504,B9) -> 0 | M9: =SUMIFS('Registro diário'!$H$6:$H$504,'Registro diário'!$D$6:$D$504,B9) -> 0 | N9: =IF(L9=0,"",M9/L9) | O9: =IF(AND(E9="Sim",L9>0),"Concluído",IF(OR(E9="Sim",L9>0),"Em andamento",IF(TODAY()>DATE(2026,11,2)+7*D9-1,"Atrasado","A fazer"))) -> A fazer | P9: =IF(F9="","",IF(OR(AND(J9<>"Sim",TODAY()>=H9),AND(K9<>"Sim",TODAY()>=I9)),"PENDENTE","ok"))
A10: Medicina Legal | B10: ML04 | C10: Traumatologia I: conceitos de trauma e lesão; consequências jurídicas dos traumas; agentes mecânicos (contundentes, cortantes, perfurantes e mistos) | D10: 4 | G10: =IF(F10="","",F10+1) | H10: =IF(F10="","",F10+7) | I10: =IF(F10="","",F10+30) | L10: =SUMIFS('Registro diário'!$G$6:$G$504,'Registro diário'!$D$6:$D$504,B10) -> 0 | M10: =SUMIFS('Registro diário'!$H$6:$H$504,'Registro diário'!$D$6:$D$504,B10) -> 0 | N10: =IF(L10=0,"",M10/L10) | O10: =IF(AND(E10="Sim",L10>0),"Concluído",IF(OR(E10="Sim",L10>0),"Em andamento",IF(TODAY()>DATE(2026,11,2)+7*D10-1,"Atrasado","A fazer"))) -> A fazer | P10: =IF(F10="","",IF(OR(AND(J10<>"Sim",TODAY()>=H10),AND(K10<>"Sim",TODAY()>=I10)),"PENDENTE","ok"))
A11: Medicina Legal | B11: ML05 | C11: Traumatologia II: armas de fogo (agentes perfurocontundentes) | D11: 5 | G11: =IF(F11="","",F11+1) | H11: =IF(F11="","",F11+7) | I11: =IF(F11="","",F11+30) | L11: =SUMIFS('Registro diário'!$G$6:$G$504,'Registro diário'!$D$6:$D$504,B11) -> 0 | M11: =SUMIFS('Registro diário'!$H$6:$H$504,'Registro diário'!$D$6:$D$504,B11) -> 0 | N11: =IF(L11=0,"",M11/L11) | O11: =IF(AND(E11="Sim",L11>0),"Concluído",IF(OR(E11="Sim",L11>0),"Em andamento",IF(TODAY()>DATE(2026,11,2)+7*D11-1,"Atrasado","A fazer"))) -> A fazer | P11: =IF(F11="","",IF(OR(AND(J11<>"Sim",TODAY()>=H11),AND(K11<>"Sim",TODAY()>=I11)),"PENDENTE","ok"))
A12: Medicina Legal | B12: ML06 | C12: Traumatologia III: agentes físicos, químicos e outros vulnerantes; idade da lesão e reação vital | D12: 6 | G12: =IF(F12="","",F12+1) | H12: =IF(F12="","",F12+7) | I12: =IF(F12="","",F12+30) | L12: =SUMIFS('Registro diário'!$G$6:$G$504,'Registro diário'!$D$6:$D$504,B12) -> 0 | M12: =SUMIFS('Registro diário'!$H$6:$H$504,'Registro diário'!$D$6:$D$504,B12) -> 0 | N12: =IF(L12=0,"",M12/L12) | O12: =IF(AND(E12="Sim",L12>0),"Concluído",IF(OR(E12="Sim",L12>0),"Em andamento",IF(TODAY()>DATE(2026,11,2)+7*D12-1,"Atrasado","A fazer"))) -> A fazer | P12: =IF(F12="","",IF(OR(AND(J12<>"Sim",TODAY()>=H12),AND(K12<>"Sim",TODAY()>=I12)),"PENDENTE","ok"))
A13: Medicina Legal | B13: ML07 | C13: Asfixiologia I: conceito e classificação etiológica; sufocação direta e indireta; enforcamento, estrangulamento e esganadura | D13: 7 | G13: =IF(F13="","",F13+1) | H13: =IF(F13="","",F13+7) | I13: =IF(F13="","",F13+30) | L13: =SUMIFS('Registro diário'!$G$6:$G$504,'Registro diário'!$D$6:$D$504,B13) -> 0 | M13: =SUMIFS('Registro diário'!$H$6:$H$504,'Registro diário'!$D$6:$D$504,B13) -> 0 | N13: =IF(L13=0,"",M13/L13) | O13: =IF(AND(E13="Sim",L13>0),"Concluído",IF(OR(E13="Sim",L13>0),"Em andamento",IF(TODAY()>DATE(2026,11,2)+7*D13-1,"Atrasado","A fazer"))) -> A fazer | P13: =IF(F13="","",IF(OR(AND(J13<>"Sim",TODAY()>=H13),AND(K13<>"Sim",TODAY()>=I13)),"PENDENTE","ok"))
A14: Medicina Legal | B14: ML08 | C14: Asfixiologia II: confinamento, soterramento e afogamento | D14: 9 | G14: =IF(F14="","",F14+1) | H14: =IF(F14="","",F14+7) | I14: =IF(F14="","",F14+30) | L14: =SUMIFS('Registro diário'!$G$6:$G$504,'Registro diário'!$D$6:$D$504,B14) -> 0 | M14: =SUMIFS('Registro diário'!$H$6:$H$504,'Registro diário'!$D$6:$D$504,B14) -> 0 | N14: =IF(L14=0,"",M14/L14) | O14: =IF(AND(E14="Sim",L14>0),"Concluído",IF(OR(E14="Sim",L14>0),"Em andamento",IF(TODAY()>DATE(2026,11,2)+7*D14-1,"Atrasado","A fazer"))) -> A fazer | P14: =IF(F14="","",IF(OR(AND(J14<>"Sim",TODAY()>=H14),AND(K14<>"Sim",TODAY()>=I14)),"PENDENTE","ok"))
A15: Medicina Legal | B15: ML09 | C15: Tanatologia I: diagnóstico da morte e consequências jurídicas; conceito moderno de morte e doação de órgãos; causa jurídica da morte (natural, violenta, suspeita, súbita) | D15: 10 | G15: =IF(F15="","",F15+1) | H15: =IF(F15="","",F15+7) | I15: =IF(F15="","",F15+30) | L15: =SUMIFS('Registro diário'!$G$6:$G$504,'Registro diário'!$D$6:$D$504,B15) -> 0 | M15: =SUMIFS('Registro diário'!$H$6:$H$504,'Registro diário'!$D$6:$D$504,B15) -> 0 | N15: =IF(L15=0,"",M15/L15) | O15: =IF(AND(E15="Sim",L15>0),"Concluído",IF(OR(E15="Sim",L15>0),"Em andamento",IF(TODAY()>DATE(2026,11,2)+7*D15-1,"Atrasado","A fazer"))) -> A fazer | P15: =IF(F15="","",IF(OR(AND(J15<>"Sim",TODAY()>=H15),AND(K15<>"Sim",TODAY()>=I15)),"PENDENTE","ok"))
A16: Medicina Legal | B16: ML10 | C16: Tanatologia II: cronotanatognose; fenômenos cadavéricos e estimativa do tempo de morte | D16: 11 | G16: =IF(F16="","",F16+1) | H16: =IF(F16="","",F16+7) | I16: =IF(F16="","",F16+30) | L16: =SUMIFS('Registro diário'!$G$6:$G$504,'Registro diário'!$D$6:$D$504,B16) -> 0 | M16: =SUMIFS('Registro diário'!$H$6:$H$504,'Registro diário'!$D$6:$D$504,B16) -> 0 | N16: =IF(L16=0,"",M16/L16) | O16: =IF(AND(E16="Sim",L16>0),"Concluído",IF(OR(E16="Sim",L16>0),"Em andamento",IF(TODAY()>DATE(2026,11,2)+7*D16-1,"Atrasado","A fazer"))) -> A fazer | P16: =IF(F16="","",IF(OR(AND(J16<>"Sim",TODAY()>=H16),AND(K16<>"Sim",TODAY()>=I16)),"PENDENTE","ok"))
A17: Medicina Legal | B17: ML11 | C17: Tanatologia III: declaração de óbito; necessidade da necrópsia médico-legal. Infortunística: acidentes do trabalho e doenças profissionais | D17: 12 | G17: =IF(F17="","",F17+1) | H17: =IF(F17="","",F17+7) | I17: =IF(F17="","",F17+30) | L17: =SUMIFS('Registro diário'!$G$6:$G$504,'Registro diário'!$D$6:$D$504,B17) -> 0 | M17: =SUMIFS('Registro diário'!$H$6:$H$504,'Registro diário'!$D$6:$D$504,B17) -> 0 | N17: =IF(L17=0,"",M17/L17) | O17: =IF(AND(E17="Sim",L17>0),"Concluído",IF(OR(E17="Sim",L17>0),"Em andamento",IF(TODAY()>DATE(2026,11,2)+7*D17-1,"Atrasado","A fazer"))) -> A fazer | P17: =IF(F17="","",IF(OR(AND(J17<>"Sim",TODAY()>=H17),AND(K17<>"Sim",TODAY()>=I17)),"PENDENTE","ok"))
A18: Medicina Legal | B18: ML12 | C18: Toxicologia I: cáusticos e venenos; intoxicações exógenas (acidentais, suicidas, criminosas); necrópsia na suspeita de intoxicação; coleta de material toxicológico | D18: 13 | G18: =IF(F18="","",F18+1) | H18: =IF(F18="","",F18+7) | I18: =IF(F18="","",F18+30) | L18: =SUMIFS('Registro diário'!$G$6:$G$504,'Registro diário'!$D$6:$D$504,B18) -> 0 | M18: =SUMIFS('Registro diário'!$H$6:$H$504,'Registro diário'!$D$6:$D$504,B18) -> 0 | N18: =IF(L18=0,"",M18/L18) | O18: =IF(AND(E18="Sim",L18>0),"Concluído",IF(OR(E18="Sim",L18>0),"Em andamento",IF(TODAY()>DATE(2026,11,2)+7*D18-1,"Atrasado","A fazer"))) -> A fazer | P18: =IF(F18="","",IF(OR(AND(J18<>"Sim",TODAY()>=H18),AND(K18<>"Sim",TODAY()>=I18)),"PENDENTE","ok"))
... A57: Direito | B57: DI17 | C57: Estatuto dos Policiais Civis do RJ (DL 218/1975) e Regulamento (Dec. 3.044/1979) | D57: 19 | G57: =IF(F57="","",F57+1) | H57: =IF(F57="","",F57+7) | I57: =IF(F57="","",F57+30) | L57: =SUMIFS('Registro diário'!$G$6:$G$504,'Registro diário'!$D$6:$D$504,B57) -> 0 | M57: =SUMIFS('Registro diário'!$H$6:$H$504,'Registro diário'!$D$6:$D$504,B57) -> 0 | N57: =IF(L57=0,"",M57/L57) | O57: =IF(AND(E57="Sim",L57>0),"Concluído",IF(OR(E57="Sim",L57>0),"Em andamento",IF(TODAY()>DATE(2026,11,2)+7*D57-1,"Atrasado","A fazer"))) -> A fazer | P57: =IF(F57="","",IF(OR(AND(J57<>"Sim",TODAY()>=H57),AND(K57<>"Sim",TODAY()>=I57)),"PENDENTE","ok"))

Sheet Registro diário
A1: Registro diário · uma linha por bloco de estudo
A2: A linha cinza é só exemplo (não entra nas contas). Preencha a partir da linha 6. Semana e % são automáticos.
A3: Código GERAL = revisão ou simulado que mistura vários tópicos.
A4: 03/11/2026 (ex.) | B4: 1 | C4: Medicina Legal | D4: ML01 | E4: Questões | F4: 60 | G4: 15 | H4: 10 | I4: 67% | J4: Exemplo: errei 2 sobre tipos de documento médico-legal
A5: Data | B5: Semana | C5: Disciplina | D5: Código do tópico | E5: Atividade | F5: Minutos | G5: Questões | H5: Acertos | I5: % acerto | J5: Observação
B6: =IF(A6="","",INT((A6-DATE(2026,11,2))/7)+1) | I6: =IF(OR(G6="",G6=0),"",H6/G6) | Z6: ML01
B7: =IF(A7="","",INT((A7-DATE(2026,11,2))/7)+1) | I7: =IF(OR(G7="",G7=0),"",H7/G7) | Z7: ML02
B8: =IF(A8="","",INT((A8-DATE(2026,11,2))/7)+1) | I8: =IF(OR(G8="",G8=0),"",H8/G8) | Z8: ML03
B9: =IF(A9="","",INT((A9-DATE(2026,11,2))/7)+1) | I9: =IF(OR(G9="",G9=0),"",H9/G9) | Z9: ML04
B10: =IF(A10="","",INT((A10-DATE(2026,11,2))/7)+1) | I10: =IF(OR(G10="",G10=0),"",H10/G10) | Z10: ML05
B11: =IF(A11="","",INT((A11-DATE(2026,11,2))/7)+1) | I11: =IF(OR(G11="",G11=0),"",H11/G11) | Z11: ML06
B12: =IF(A12="","",INT((A12-DATE(2026,11,2))/7)+1) | I12: =IF(OR(G12="",G12=0),"",H12/G12) | Z12: ML07
B13: =IF(A13="","",INT((A13-DATE(2026,11,2))/7)+1) | I13: =IF(OR(G13="",G13=0),"",H13/G13) | Z13: ML08
B14: =IF(A14="","",INT((A14-DATE(2026,11,2))/7)+1) | I14: =IF(OR(G14="",G14=0),"",H14/G14) | Z14: ML09
B15: =IF(A15="","",INT((A15-DATE(2026,11,2))/7)+1) | I15: =IF(OR(G15="",G15=0),"",H15/G15) | Z15: ML10
B16: =IF(A16="","",INT((A16-DATE(2026,11,2))/7)+1) | I16: =IF(OR(G16="",G16=0),"",H16/G16) | Z16: ML11
B17: =IF(A17="","",INT((A17-DATE(2026,11,2))/7)+1) | I17: =IF(OR(G17="",G17=0),"",H17/G17) | Z17: ML12
... B57: =IF(A57="","",INT((A57-DATE(2026,11,2))/7)+1) | I57: =IF(OR(G57="",G57=0),"",H57/G57) | Z57: GERAL
B58: =IF(A58="","",INT((A58-DATE(2026,11,2))/7)+1) | I58: =IF(OR(G58="",G58=0),"",H58/G58)
B59: =IF(A59="","",INT((A59-DATE(2026,11,2))/7)+1) | I59: =IF(OR(G59="",G59=0),"",H59/G59)
B60: =IF(A60="","",INT((A60-DATE(2026,11,2))/7)+1) | I60: =IF(OR(G60="",G60=0),"",H60/G60)
B61: =IF(A61="","",INT((A61-DATE(2026,11,2))/7)+1) | I61: =IF(OR(G61="",G61=0),"",H61/G61)
B62: =IF(A62="","",INT((A62-DATE(2026,11,2))/7)+1) | I62: =IF(OR(G62="",G62=0),"",H62/G62)
B63: =IF(A63="","",INT((A63-DATE(2026,11,2))/7)+1) | I63: =IF(OR(G63="",G63=0),"",H63/G63)
B64: =IF(A64="","",INT((A64-DATE(2026,11,2))/7)+1) | I64: =IF(OR(G64="",G64=0),"",H64/G64)
B65: =IF(A65="","",INT((A65-DATE(2026,11,2))/7)+1) | I65: =IF(OR(G65="",G65=0),"",H65/G65)
B66: =IF(A66="","",INT((A66-DATE(2026,11,2))/7)+1) | I66: =IF(OR(G66="",G66=0),"",H66/G66)
B67: =IF(A67="","",INT((A67-DATE(2026,11,2))/7)+1) | I67: =IF(OR(G67="",G67=0),"",H67/G67)
B68: =IF(A68="","",INT((A68-DATE(2026,11,2))/7)+1) | I68: =IF(OR(G68="",G68=0),"",H68/G68)
B69: =IF(A69="","",INT((A69-DATE(2026,11,2))/7)+1) | I69: =IF(OR(G69="",G69=0),"",H69/G69)
... B504: =IF(A504="","",INT((A504-DATE(2026,11,2))/7)+1) | I504: =IF(OR(G504="",G504=0),"",H504/G504)

Sheet Painel semanal
A1: Painel semanal
A2: Tudo aqui é automático (vem do Registro diário e do Edital). Leia a coluna ALERTA todo domingo.
A3: Edital concluído hoje | C3: =Edital!B3 -> 0 | D3: Revisões pendentes | F3: =Edital!B4 -> 0 | G3: Horas totais | H3: =SUM(D7:D32) -> 0 | I3: Questões totais | K3: =SUM(G7:G32) -> 0
A6: Semana | B6: Datas | C6: Horas plan. | D6: Horas exec. | E6: % execução | F6: Meta questões | G6: Questões feitas | H6: Acerto geral | I6: Acerto ML | J6: Acerto Port. | K6: Acerto Dir. | L6: Edital previsto (acum.) | M6: ALERTA
A7: 1 | B7: 02/11–08/11/26 | C7: 10 | D7: =SUMIFS('Registro diário'!$F$6:$F$504,'Registro diário'!$B$6:$B$504,A7)/60 -> 0 | E7: =IF(D7=0,"",D7/C7) | F7: 50 | G7: =SUMIFS('Registro diário'!$G$6:$G$504,'Registro diário'!$B$6:$B$504,A7) -> 0 | H7: =IF(G7=0,"",SUMIFS('Registro diário'!$H$6:$H$504,'Registro diário'!$B$6:$B$504,A7)/G7) | I7: =IF(SUMIFS('Registro diário'!$G$6:$G$504,'Registro diário'!$B$6:$B$504,$A7,'Registro diário'!$C$6:$C$504,"Medicina Legal")=0,"",SUMIFS('Registro diário'!$H$6:$H$504,'Registro diário'!$B$6:$B$504,$A7,'Registro diário'!$C$6:$C$504,"Medicina Legal")/SUMIFS('Registro diário'!$G$6:$G$504,'Registro diário'!$B$6:$B$504,$A7,'Registro diário'!$C$6:$C$504,"Medicina Legal")) | J7: =IF(SUMIFS('Registro diário'!$G$6:$G$504,'Registro diário'!$B$6:$B$504,$A7,'Registro diário'!$C$6:$C$504,"Português")=0,"",SUMIFS('Registro diário'!$H$6:$H$504,'Registro diário'!$B$6:$B$504,$A7,'Registro diário'!$C$6:$C$504,"Português")/SUMIFS('Registro diário'!$G$6:$G$504,'Registro diário'!$B$6:$B$504,$A7,'Registro diário'!$C$6:$C$504,"Português")) | K7: =IF(SUMIFS('Registro diário'!$G$6:$G$504,'Registro diário'!$B$6:$B$504,$A7,'Registro diário'!$C$6:$C$504,"Direito")=0,"",SUMIFS('Registro diário'!$H$6:$H$504,'Registro diário'!$B$6:$B$504,$A7,'Registro diário'!$C$6:$C$504,"Direito")/SUMIFS('Registro diário'!$G$6:$G$504,'Registro diário'!$B$6:$B$504,$A7,'Registro diário'!$C$6:$C$504,"Direito")) | L7: =COUNTIF(Edital!$D$7:$D$57,"<="&A7)/51 -> 0.058823529 | M7: =IF(D7=0,"",IF(IF(AND(ISNUMBER(E7),E7<0.8),"Horas abaixo de 80%. ","")&IF(AND(ISNUMBER(I7),I7<0.6),"ML abaixo de 60%: +1 bloco. ","")&IF(AND(ISNUMBER(J7),J7<0.6),"Português abaixo de 60%: +1 bloco. ","")&IF(AND(ISNUMBER(K7),K7<0.6),"Direito abaixo de 60%: +1 bloco. ","")&IF(AND(G7>0,G7<0.8*F7),"Questões abaixo da meta. ","")="","Dentro do plano",IF(AND(ISNUMBER(E7),E7<0.8),"Horas abaixo de 80%. ","")&IF(AND(ISNUMBER(I7),I7<0.6),"ML abaixo de 60%: +1 bloco. ","")&IF(AND(ISNUMBER(J7),J7<0.6),"Português abaixo de 60%: +1 bloco. ","")&IF(AND(ISNUMBER(K7),K7<0.6),"Direito abaixo de 60%: +1 bloco. ","")&IF(AND(G7>0,G7<0.8*F7),"Questões abaixo da meta. ","")))
A8: 2 | B8: 09/11–15/11/26 | C8: 10 | D8: =SUMIFS('Registro diário'!$F$6:$F$504,'Registro diário'!$B$6:$B$504,A8)/60 -> 0 | E8: =IF(D8=0,"",D8/C8) | F8: 50 | G8: =SUMIFS('Registro diário'!$G$6:$G$504,'Registro diário'!$B$6:$B$504,A8) -> 0 | H8: =IF(G8=0,"",SUMIFS('Registro diário'!$H$6:$H$504,'Registro diário'!$B$6:$B$504,A8)/G8) | I8: =IF(SUMIFS('Registro diário'!$G$6:$G$504,'Registro diário'!$B$6:$B$504,$A8,'Registro diário'!$C$6:$C$504,"Medicina Legal")=0,"",SUMIFS('Registro diário'!$H$6:$H$504,'Registro diário'!$B$6:$B$504,$A8,'Registro diário'!$C$6:$C$504,"Medicina Legal")/SUMIFS('Registro diário'!$G$6:$G$504,'Registro diário'!$B$6:$B$504,$A8,'Registro diário'!$C$6:$C$504,"Medicina Legal")) | J8: =IF(SUMIFS('Registro diário'!$G$6:$G$504,'Registro diário'!$B$6:$B$504,$A8,'Registro diário'!$C$6:$C$504,"Português")=0,"",SUMIFS('Registro diário'!$H$6:$H$504,'Registro diário'!$B$6:$B$504,$A8,'Registro diário'!$C$6:$C$504,"Português")/SUMIFS('Registro diário'!$G$6:$G$504,'Registro diário'!$B$6:$B$504,$A8,'Registro diário'!$C$6:$C$504,"Português")) | K8: =IF(SUMIFS('Registro diário'!$G$6:$G$504,'Registro diário'!$B$6:$B$504,$A8,'Registro diário'!$C$6:$C$504,"Direito")=0,"",SUMIFS('Registro diário'!$H$6:$H$504,'Registro diário'!$B$6:$B$504,$A8,'Registro diário'!$C$6:$C$504,"Direito")/SUMIFS('Registro diário'!$G$6:$G$504,'Registro diário'!$B$6:$B$504,$A8,'Registro diário'!$C$6:$C$504,"Direito")) | L8: =COUNTIF(Edital!$D$7:$D$57,"<="&A8)/51 -> 0.11764706 | M8: =IF(D8=0,"",IF(IF(AND(ISNUMBER(E8),E8<0.8),"Horas abaixo de 80%. ","")&IF(AND(ISNUMBER(I8),I8<0.6),"ML abaixo de 60%: +1 bloco. ","")&IF(AND(ISNUMBER(J8),J8<0.6),"Português abaixo de 60%: +1 bloco. ","")&IF(AND(ISNUMBER(K8),K8<0.6),"Direito abaixo de 60%: +1 bloco. ","")&IF(AND(G8>0,G8<0.8*F8),"Questões abaixo da meta. ","")="","Dentro do plano",IF(AND(ISNUMBER(E8),E8<0.8),"Horas abaixo de 80%. ","")&IF(AND(ISNUMBER(I8),I8<0.6),"ML abaixo de 60%: +1 bloco. ","")&IF(AND(ISNUMBER(J8),J8<0.6),"Português abaixo de 60%: +1 bloco. ","")&IF(AND(ISNUMBER(K8),K8<0.6),"Direito abaixo de 60%: +1 bloco. ","")&IF(AND(G8>0,G8<0.8*F8),"Questões abaixo da meta. ","")))
A9: 3 | B9: 16/11–22/11/26 | C9: 10 | D9: =SUMIFS('Registro diário'!$F$6:$F$504,'Registro diário'!$B$6:$B$504,A9)/60 -> 0 | E9: =IF(D9=0,"",D9/C9) | F9: 50 | G9: =SUMIFS('Registro diário'!$G$6:$G$504,'Registro diário'!$B$6:$B$504,A9) -> 0 | H9: =IF(G9=0,"",SUMIFS('Registro diário'!$H$6:$H$504,'Registro diário'!$B$6:$B$504,A9)/G9) | I9: =IF(SUMIFS('Registro diário'!$G$6:$G$504,'Registro diário'!$B$6:$B$504,$A9,'Registro diário'!$C$6:$C$504,"Medicina Legal")=0,"",SUMIFS('Registro diário'!$H$6:$H$504,'Registro diário'!$B$6:$B$504,$A9,'Registro diário'!$C$6:$C$504,"Medicina Legal")/SUMIFS('Registro diário'!$G$6:$G$504,'Registro diário'!$B$6:$B$504,$A9,'Registro diário'!$C$6:$C$504,"Medicina Legal")) | J9: =IF(SUMIFS('Registro diário'!$G$6:$G$504,'Registro diário'!$B$6:$B$504,$A9,'Registro diário'!$C$6:$C$504,"Português")=0,"",SUMIFS('Registro diário'!$H$6:$H$504,'Registro diário'!$B$6:$B$504,$A9,'Registro diário'!$C$6:$C$504,"Português")/SUMIFS('Registro diário'!$G$6:$G$504,'Registro diário'!$B$6:$B$504,$A9,'Registro diário'!$C$6:$C$504,"Português")) | K9: =IF(SUMIFS('Registro diário'!$G$6:$G$504,'Registro diário'!$B$6:$B$504,$A9,'Registro diário'!$C$6:$C$504,"Direito")=0,"",SUMIFS('Registro diário'!$H$6:$H$504,'Registro diário'!$B$6:$B$504,$A9,'Registro diário'!$C$6:$C$504,"Direito")/SUMIFS('Registro diário'!$G$6:$G$504,'Registro diário'!$B$6:$B$504,$A9,'Registro diário'!$C$6:$C$504,"Direito")) | L9: =COUNTIF(Edital!$D$7:$D$57,"<="&A9)/51 -> 0.17647059 | M9: =IF(D9=0,"",IF(IF(AND(ISNUMBER(E9),E9<0.8),"Horas abaixo de 80%. ","")&IF(AND(ISNUMBER(I9),I9<0.6),"ML abaixo de 60%: +1 bloco. ","")&IF(AND(ISNUMBER(J9),J9<0.6),"Português abaixo de 60%: +1 bloco. ","")&IF(AND(ISNUMBER(K9),K9<0.6),"Direito abaixo de 60%: +1 bloco. ","")&IF(AND(G9>0,G9<0.8*F9),"Questões abaixo da meta. ","")="","Dentro do plano",IF(AND(ISNUMBER(E9),E9<0.8),"Horas abaixo de 80%. ","")&IF(AND(ISNUMBER(I9),I9<0.6),"ML abaixo de 60%: +1 bloco. ","")&IF(AND(ISNUMBER(J9),J9<0.6),"Português abaixo de 60%: +1 bloco. ","")&IF(AND(ISNUMBER(K9),K9<0.6),"Direito abaixo de 60%: +1 bloco. ","")&IF(AND(G9>0,G9<0.8*F9),"Questões abaixo da meta. ","")))
A10: 4 | B10: 23/11–29/11/26 | C10: 10 | D10: =SUMIFS('Registro diário'!$F$6:$F$504,'Registro diário'!$B$6:$B$504,A10)/60 -> 0 | E10: =IF(D10=0,"",D10/C10) | F10: 50 | G10: =SUMIFS('Registro diário'!$G$6:$G$504,'Registro diário'!$B$6:$B$504,A10) -> 0 | H10: =IF(G10=0,"",SUMIFS('Registro diário'!$H$6:$H$504,'Registro diário'!$B$6:$B$504,A10)/G10) | I10: =IF(SUMIFS('Registro diário'!$G$6:$G$504,'Registro diário'!$B$6:$B$504,$A10,'Registro diário'!$C$6:$C$504,"Medicina Legal")=0,"",SUMIFS('Registro diário'!$H$6:$H$504,'Registro diário'!$B$6:$B$504,$A10,'Registro diário'!$C$6:$C$504,"Medicina Legal")/SUMIFS('Registro diário'!$G$6:$G$504,'Registro diário'!$B$6:$B$504,$A10,'Registro diário'!$C$6:$C$504,"Medicina Legal")) | J10: =IF(SUMIFS('Registro diário'!$G$6:$G$504,'Registro diário'!$B$6:$B$504,$A10,'Registro diário'!$C$6:$C$504,"Português")=0,"",SUMIFS('Registro diário'!$H$6:$H$504,'Registro diário'!$B$6:$B$504,$A10,'Registro diário'!$C$6:$C$504,"Português")/SUMIFS('Registro diário'!$G$6:$G$504,'Registro diário'!$B$6:$B$504,$A10,'Registro diário'!$C$6:$C$504,"Português")) | K10: =IF(SUMIFS('Registro diário'!$G$6:$G$504,'Registro diário'!$B$6:$B$504,$A10,'Registro diário'!$C$6:$C$504,"Direito")=0,"",SUMIFS('Registro diário'!$H$6:$H$504,'Registro diário'!$B$6:$B$504,$A10,'Registro diário'!$C$6:$C$504,"Direito")/SUMIFS('Registro diário'!$G$6:$G$504,'Registro diário'!$B$6:$B$504,$A10,'Registro diário'!$C$6:$C$504,"Direito")) | L10: =COUNTIF(Edital!$D$7:$D$57,"<="&A10)/51 -> 0.23529412 | M10: =IF(D10=0,"",IF(IF(AND(ISNUMBER(E10),E10<0.8),"Horas abaixo de 80%. ","")&IF(AND(ISNUMBER(I10),I10<0.6),"ML abaixo de 60%: +1 bloco. ","")&IF(AND(ISNUMBER(J10),J10<0.6),"Português abaixo de 60%: +1 bloco. ","")&IF(AND(ISNUMBER(K10),K10<0.6),"Direito abaixo de 60%: +1 bloco. ","")&IF(AND(G10>0,G10<0.8*F10),"Questões abaixo da meta. ","")="","Dentro do plano",IF(AND(ISNUMBER(E10),E10<0.8),"Horas abaixo de 80%. ","")&IF(AND(ISNUMBER(I10),I10<0.6),"ML abaixo de 60%: +1 bloco. ","")&IF(AND(ISNUMBER(J10),J10<0.6),"Português abaixo de 60%: +1 bloco. ","")&IF(AND(ISNUMBER(K10),K10<0.6),"Direito abaixo de 60%: +1 bloco. ","")&IF(AND(G10>0,G10<0.8*F10),"Questões abaixo da meta. ","")))
A11: 5 | B11: 30/11–06/12/26 | C11: 10 | D11: =SUMIFS('Registro diário'!$F$6:$F$504,'Registro diário'!$B$6:$B$504,A11)/60 -> 0 | E11: =IF(D11=0,"",D11/C11) | F11: 50 | G11: =SUMIFS('Registro diário'!$G$6:$G$504,'Registro diário'!$B$6:$B$504,A11) -> 0 | H11: =IF(G11=0,"",SUMIFS('Registro diário'!$H$6:$H$504,'Registro diário'!$B$6:$B$504,A11)/G11) | I11: =IF(SUMIFS('Registro diário'!$G$6:$G$504,'Registro diário'!$B$6:$B$504,$A11,'Registro diário'!$C$6:$C$504,"Medicina Legal")=0,"",SUMIFS('Registro diário'!$H$6:$H$504,'Registro diário'!$B$6:$B$504,$A11,'Registro diário'!$C$6:$C$504,"Medicina Legal")/SUMIFS('Registro diário'!$G$6:$G$504,'Registro diário'!$B$6:$B$504,$A11,'Registro diário'!$C$6:$C$504,"Medicina Legal")) | J11: =IF(SUMIFS('Registro diário'!$G$6:$G$504,'Registro diário'!$B$6:$B$504,$A11,'Registro diário'!$C$6:$C$504,"Português")=0,"",SUMIFS('Registro diário'!$H$6:$H$504,'Registro diário'!$B$6:$B$504,$A11,'Registro diário'!$C$6:$C$504,"Português")/SUMIFS('Registro diário'!$G$6:$G$504,'Registro diário'!$B$6:$B$504,$A11,'Registro diário'!$C$6:$C$504,"Português")) | K11: =IF(SUMIFS('Registro diário'!$G$6:$G$504,'Registro diário'!$B$6:$B$504,$A11,'Registro diário'!$C$6:$C$504,"Direito")=0,"",SUMIFS('Registro diário'!$H$6:$H$504,'Registro diário'!$B$6:$B$504,$A11,'Registro diário'!$C$6:$C$504,"Direito")/SUMIFS('Registro diário'!$G$6:$G$504,'Registro diário'!$B$6:$B$504,$A11,'Registro diário'!$C$6:$C$504,"Direito")) | L11: =COUNTIF(Edital!$D$7:$D$57,"<="&A11)/51 -> 0.29411765 | M11: =IF(D11=0,"",IF(IF(AND(ISNUMBER(E11),E11<0.8),"Horas abaixo de 80%. ","")&IF(AND(ISNUMBER(I11),I11<0.6),"ML abaixo de 60%: +1 bloco. ","")&IF(AND(ISNUMBER(J11),J11<0.6),"Português abaixo de 60%: +1 bloco. ","")&IF(AND(ISNUMBER(K11),K11<0.6),"Direito abaixo de 60%: +1 bloco. ","")&IF(AND(G11>0,G11<0.8*F11),"Questões abaixo da meta. ","")="","Dentro do plano",IF(AND(ISNUMBER(E11),E11<0.8),"Horas abaixo de 80%. ","")&IF(AND(ISNUMBER(I11),I11<0.6),"ML abaixo de 60%: +1 bloco. ","")&IF(AND(ISNUMBER(J11),J11<0.6),"Português abaixo de 60%: +1 bloco. ","")&IF(AND(ISNUMBER(K11),K11<0.6),"Direito abaixo de 60%: +1 bloco. ","")&IF(AND(G11>0,G11<0.8*F11),"Questões abaixo da meta. ","")))
A12: 6 | B12: 07/12–13/12/26 | C12: 10 | D12: =SUMIFS('Registro diário'!$F$6:$F$504,'Registro diário'!$B$6:$B$504,A12)/60 -> 0 | E12: =IF(D12=0,"",D12/C12) | F12: 50 | G12: =SUMIFS('Registro diário'!$G$6:$G$504,'Registro diário'!$B$6:$B$504,A12) -> 0 | H12: =IF(G12=0,"",SUMIFS('Registro diário'!$H$6:$H$504,'Registro diário'!$B$6:$B$504,A12)/G12) | I12: =IF(SUMIFS('Registro diário'!$G$6:$G$504,'Registro diário'!$B$6:$B$504,$A12,'Registro diário'!$C$6:$C$504,"Medicina Legal")=0,"",SUMIFS('Registro diário'!$H$6:$H$504,'Registro diário'!$B$6:$B$504,$A12,'Registro diário'!$C$6:$C$504,"Medicina Legal")/SUMIFS('Registro diário'!$G$6:$G$504,'Registro diário'!$B$6:$B$504,$A12,'Registro diário'!$C$6:$C$504,"Medicina Legal")) | J12: =IF(SUMIFS('Registro diário'!$G$6:$G$504,'Registro diário'!$B$6:$B$504,$A12,'Registro diário'!$C$6:$C$504,"Português")=0,"",SUMIFS('Registro diário'!$H$6:$H$504,'Registro diário'!$B$6:$B$504,$A12,'Registro diário'!$C$6:$C$504,"Português")/SUMIFS('Registro diário'!$G$6:$G$504,'Registro diário'!$B$6:$B$504,$A12,'Registro diário'!$C$6:$C$504,"Português")) | K12: =IF(SUMIFS('Registro diário'!$G$6:$G$504,'Registro diário'!$B$6:$B$504,$A12,'Registro diário'!$C$6:$C$504,"Direito")=0,"",SUMIFS('Registro diário'!$H$6:$H$504,'Registro diário'!$B$6:$B$504,$A12,'Registro diário'!$C$6:$C$504,"Direito")/SUMIFS('Registro diário'!$G$6:$G$504,'Registro diário'!$B$6:$B$504,$A12,'Registro diário'!$C$6:$C$504,"Direito")) | L12: =COUNTIF(Edital!$D$7:$D$57,"<="&A12)/51 -> 0.35294118 | M12: =IF(D12=0,"",IF(IF(AND(ISNUMBER(E12),E12<0.8),"Horas abaixo de 80%. ","")&IF(AND(ISNUMBER(I12),I12<0.6),"ML abaixo de 60%: +1 bloco. ","")&IF(AND(ISNUMBER(J12),J12<0.6),"Português abaixo de 60%: +1 bloco. ","")&IF(AND(ISNUMBER(K12),K12<0.6),"Direito abaixo de 60%: +1 bloco. ","")&IF(AND(G12>0,G12<0.8*F12),"Questões abaixo da meta. ","")="","Dentro do plano",IF(AND(ISNUMBER(E12),E12<0.8),"Horas abaixo de 80%. ","")&IF(AND(ISNUMBER(I12),I12<0.6),"ML abaixo de 60%: +1 bloco. ","")&IF(AND(ISNUMBER(J12),J12<0.6),"Português abaixo de 60%: +1 bloco. ","")&IF(AND(ISNUMBER(K12),K12<0.6),"Direito abaixo de 60%: +1 bloco. ","")&IF(AND(G12>0,G12<0.8*F12),"Questões abaixo da meta. ","")))
A13: 7 | B13: 14/12–20/12/26 | C13: 10 | D13: =SUMIFS('Registro diário'!$F$6:$F$504,'Registro diário'!$B$6:$B$504,A13)/60 -> 0 | E13: =IF(D13=0,"",D13/C13) | F13: 50 | G13: =SUMIFS('Registro diário'!$G$6:$G$504,'Registro diário'!$B$6:$B$504,A13) -> 0 | H13: =IF(G13=0,"",SUMIFS('Registro diário'!$H$6:$H$504,'Registro diário'!$B$6:$B$504,A13)/G13) | I13: =IF(SUMIFS('Registro diário'!$G$6:$G$504,'Registro diário'!$B$6:$B$504,$A13,'Registro diário'!$C$6:$C$504,"Medicina Legal")=0,"",SUMIFS('Registro diário'!$H$6:$H$504,'Registro diário'!$B$6:$B$504,$A13,'Registro diário'!$C$6:$C$504,"Medicina Legal")/SUMIFS('Registro diário'!$G$6:$G$504,'Registro diário'!$B$6:$B$504,$A13,'Registro diário'!$C$6:$C$504,"Medicina Legal")) | J13: =IF(SUMIFS('Registro diário'!$G$6:$G$504,'Registro diário'!$B$6:$B$504,$A13,'Registro diário'!$C$6:$C$504,"Português")=0,"",SUMIFS('Registro diário'!$H$6:$H$504,'Registro diário'!$B$6:$B$504,$A13,'Registro diário'!$C$6:$C$504,"Português")/SUMIFS('Registro diário'!$G$6:$G$504,'Registro diário'!$B$6:$B$504,$A13,'Registro diário'!$C$6:$C$504,"Português")) | K13: =IF(SUMIFS('Registro diário'!$G$6:$G$504,'Registro diário'!$B$6:$B$504,$A13,'Registro diário'!$C$6:$C$504,"Direito")=0,"",SUMIFS('Registro diário'!$H$6:$H$504,'Registro diário'!$B$6:$B$504,$A13,'Registro diário'!$C$6:$C$504,"Direito")/SUMIFS('Registro diário'!$G$6:$G$504,'Registro diário'!$B$6:$B$504,$A13,'Registro diário'!$C$6:$C$504,"Direito")) | L13: =COUNTIF(Edital!$D$7:$D$57,"<="&A13)/51 -> 0.41176471 | M13: =IF(D13=0,"",IF(IF(AND(ISNUMBER(E13),E13<0.8),"Horas abaixo de 80%. ","")&IF(AND(ISNUMBER(I13),I13<0.6),"ML abaixo de 60%: +1 bloco. ","")&IF(AND(ISNUMBER(J13),J13<0.6),"Português abaixo de 60%: +1 bloco. ","")&IF(AND(ISNUMBER(K13),K13<0.6),"Direito abaixo de 60%: +1 bloco. ","")&IF(AND(G13>0,G13<0.8*F13),"Questões abaixo da meta. ","")="","Dentro do plano",IF(AND(ISNUMBER(E13),E13<0.8),"Horas abaixo de 80%. ","")&IF(AND(ISNUMBER(I13),I13<0.6),"ML abaixo de 60%: +1 bloco. ","")&IF(AND(ISNUMBER(J13),J13<0.6),"Português abaixo de 60%: +1 bloco. ","")&IF(AND(ISNUMBER(K13),K13<0.6),"Direito abaixo de 60%: +1 bloco. ","")&IF(AND(G13>0,G13<0.8*F13),"Questões abaixo da meta. ","")))
A14: 8 | B14: 21/12–27/12/26 | C14: 5 | D14: =SUMIFS('Registro diário'!$F$6:$F$504,'Registro diário'!$B$6:$B$504,A14)/60 -> 0 | E14: =IF(D14=0,"",D14/C14) | F14: 30 | G14: =SUMIFS('Registro diário'!$G$6:$G$504,'Registro diário'!$B$6:$B$504,A14) -> 0 | H14: =IF(G14=0,"",SUMIFS('Registro diário'!$H$6:$H$504,'Registro diário'!$B$6:$B$504,A14)/G14) | I14: =IF(SUMIFS('Registro diário'!$G$6:$G$504,'Registro diário'!$B$6:$B$504,$A14,'Registro diário'!$C$6:$C$504,"Medicina Legal")=0,"",SUMIFS('Registro diário'!$H$6:$H$504,'Registro diário'!$B$6:$B$504,$A14,'Registro diário'!$C$6:$C$504,"Medicina Legal")/SUMIFS('Registro diário'!$G$6:$G$504,'Registro diário'!$B$6:$B$504,$A14,'Registro diário'!$C$6:$C$504,"Medicina Legal")) | J14: =IF(SUMIFS('Registro diário'!$G$6:$G$504,'Registro diário'!$B$6:$B$504,$A14,'Registro diário'!$C$6:$C$504,"Português")=0,"",SUMIFS('Registro diário'!$H$6:$H$504,'Registro diário'!$B$6:$B$504,$A14,'Registro diário'!$C$6:$C$504,"Português")/SUMIFS('Registro diário'!$G$6:$G$504,'Registro diário'!$B$6:$B$504,$A14,'Registro diário'!$C$6:$C$504,"Português")) | K14: =IF(SUMIFS('Registro diário'!$G$6:$G$504,'Registro diário'!$B$6:$B$504,$A14,'Registro diário'!$C$6:$C$504,"Direito")=0,"",SUMIFS('Registro diário'!$H$6:$H$504,'Registro diário'!$B$6:$B$504,$A14,'Registro diário'!$C$6:$C$504,"Direito")/SUMIFS('Registro diário'!$G$6:$G$504,'Registro diário'!$B$6:$B$504,$A14,'Registro diário'!$C$6:$C$504,"Direito")) | L14: =COUNTIF(Edital!$D$7:$D$57,"<="&A14)/51 -> 0.41176471 | M14: =IF(D14=0,"",IF(IF(AND(ISNUMBER(E14),E14<0.8),"Horas abaixo de 80%. ","")&IF(AND(ISNUMBER(I14),I14<0.6),"ML abaixo de 60%: +1 bloco. ","")&IF(AND(ISNUMBER(J14),J14<0.6),"Português abaixo de 60%: +1 bloco. ","")&IF(AND(ISNUMBER(K14),K14<0.6),"Direito abaixo de 60%: +1 bloco. ","")&IF(AND(G14>0,G14<0.8*F14),"Questões abaixo da meta. ","")="","Dentro do plano",IF(AND(ISNUMBER(E14),E14<0.8),"Horas abaixo de 80%. ","")&IF(AND(ISNUMBER(I14),I14<0.6),"ML abaixo de 60%: +1 bloco. ","")&IF(AND(ISNUMBER(J14),J14<0.6),"Português abaixo de 60%: +1 bloco. ","")&IF(AND(ISNUMBER(K14),K14<0.6),"Direito abaixo de 60%: +1 bloco. ","")&IF(AND(G14>0,G14<0.8*F14),"Questões abaixo da meta. ","")))
A15: 9 | B15: 28/12–03/01/27 | C15: 10 | D15: =SUMIFS('Registro diário'!$F$6:$F$504,'Registro diário'!$B$6:$B$504,A15)/60 -> 0 | E15: =IF(D15=0,"",D15/C15) | F15: 70 | G15: =SUMIFS('Registro diário'!$G$6:$G$504,'Registro diário'!$B$6:$B$504,A15) -> 0 | H15: =IF(G15=0,"",SUMIFS('Registro diário'!$H$6:$H$504,'Registro diário'!$B$6:$B$504,A15)/G15) | I15: =IF(SUMIFS('Registro diário'!$G$6:$G$504,'Registro diário'!$B$6:$B$504,$A15,'Registro diário'!$C$6:$C$504,"Medicina Legal")=0,"",SUMIFS('Registro diário'!$H$6:$H$504,'Registro diário'!$B$6:$B$504,$A15,'Registro diário'!$C$6:$C$504,"Medicina Legal")/SUMIFS('Registro diário'!$G$6:$G$504,'Registro diário'!$B$6:$B$504,$A15,'Registro diário'!$C$6:$C$504,"Medicina Legal")) | J15: =IF(SUMIFS('Registro diário'!$G$6:$G$504,'Registro diário'!$B$6:$B$504,$A15,'Registro diário'!$C$6:$C$504,"Português")=0,"",SUMIFS('Registro diário'!$H$6:$H$504,'Registro diário'!$B$6:$B$504,$A15,'Registro diário'!$C$6:$C$504,"Português")/SUMIFS('Registro diário'!$G$6:$G$504,'Registro diário'!$B$6:$B$504,$A15,'Registro diário'!$C$6:$C$504,"Português")) | K15: =IF(SUMIFS('Registro diário'!$G$6:$G$504,'Registro diário'!$B$6:$B$504,$A15,'Registro diário'!$C$6:$C$504,"Direito")=0,"",SUMIFS('Registro diário'!$H$6:$H$504,'Registro diário'!$B$6:$B$504,$A15,'Registro diário'!$C$6:$C$504,"Direito")/SUMIFS('Registro diário'!$G$6:$G$504,'Registro diário'!$B$6:$B$504,$A15,'Registro diário'!$C$6:$C$504,"Direito")) | L15: =COUNTIF(Edital!$D$7:$D$57,"<="&A15)/51 -> 0.47058824 | M15: =IF(D15=0,"",IF(IF(AND(ISNUMBER(E15),E15<0.8),"Horas abaixo de 80%. ","")&IF(AND(ISNUMBER(I15),I15<0.6),"ML abaixo de 60%: +1 bloco. ","")&IF(AND(ISNUMBER(J15),J15<0.6),"Português abaixo de 60%: +1 bloco. ","")&IF(AND(ISNUMBER(K15),K15<0.6),"Direito abaixo de 60%: +1 bloco. ","")&IF(AND(G15>0,G15<0.8*F15),"Questões abaixo da meta. ","")="","Dentro do plano",IF(AND(ISNUMBER(E15),E15<0.8),"Horas abaixo de 80%. ","")&IF(AND(ISNUMBER(I15),I15<0.6),"ML abaixo de 60%: +1 bloco. ","")&IF(AND(ISNUMBER(J15),J15<0.6),"Português abaixo de 60%: +1 bloco. ","")&IF(AND(ISNUMBER(K15),K15<0.6),"Direito abaixo de 60%: +1 bloco. ","")&IF(AND(G15>0,G15<0.8*F15),"Questões abaixo da meta. ","")))
A16: 10 | B16: 04/01–10/01/27 | C16: 10 | D16: =SUMIFS('Registro diário'!$F$6:$F$504,'Registro diário'!$B$6:$B$504,A16)/60 -> 0 | E16: =IF(D16=0,"",D16/C16) | F16: 70 | G16: =SUMIFS('Registro diário'!$G$6:$G$504,'Registro diário'!$B$6:$B$504,A16) -> 0 | H16: =IF(G16=0,"",SUMIFS('Registro diário'!$H$6:$H$504,'Registro diário'!$B$6:$B$504,A16)/G16) | I16: =IF(SUMIFS('Registro diário'!$G$6:$G$504,'Registro diário'!$B$6:$B$504,$A16,'Registro diário'!$C$6:$C$504,"Medicina Legal")=0,"",SUMIFS('Registro diário'!$H$6:$H$504,'Registro diário'!$B$6:$B$504,$A16,'Registro diário'!$C$6:$C$504,"Medicina Legal")/SUMIFS('Registro diário'!$G$6:$G$504,'Registro diário'!$B$6:$B$504,$A16,'Registro diário'!$C$6:$C$504,"Medicina Legal")) | J16: =IF(SUMIFS('Registro diário'!$G$6:$G$504,'Registro diário'!$B$6:$B$504,$A16,'Registro diário'!$C$6:$C$504,"Português")=0,"",SUMIFS('Registro diário'!$H$6:$H$504,'Registro diário'!$B$6:$B$504,$A16,'Registro diário'!$C$6:$C$504,"Português")/SUMIFS('Registro diário'!$G$6:$G$504,'Registro diário'!$B$6:$B$504,$A16,'Registro diário'!$C$6:$C$504,"Português")) | K16: =IF(SUMIFS('Registro diário'!$G$6:$G$504,'Registro diário'!$B$6:$B$504,$A16,'Registro diário'!$C$6:$C$504,"Direito")=0,"",SUMIFS('Registro diário'!$H$6:$H$504,'Registro diário'!$B$6:$B$504,$A16,'Registro diário'!$C$6:$C$504,"Direito")/SUMIFS('Registro diário'!$G$6:$G$504,'Registro diário'!$B$6:$B$504,$A16,'Registro diário'!$C$6:$C$504,"Direito")) | L16: =COUNTIF(Edital!$D$7:$D$57,"<="&A16)/51 -> 0.52941176 | M16: =IF(D16=0,"",IF(IF(AND(ISNUMBER(E16),E16<0.8),"Horas abaixo de 80%. ","")&IF(AND(ISNUMBER(I16),I16<0.6),"ML abaixo de 60%: +1 bloco. ","")&IF(AND(ISNUMBER(J16),J16<0.6),"Português abaixo de 60%: +1 bloco. ","")&IF(AND(ISNUMBER(K16),K16<0.6),"Direito abaixo de 60%: +1 bloco. ","")&IF(AND(G16>0,G16<0.8*F16),"Questões abaixo da meta. ","")="","Dentro do plano",IF(AND(ISNUMBER(E16),E16<0.8),"Horas abaixo de 80%. ","")&IF(AND(ISNUMBER(I16),I16<0.6),"ML abaixo de 60%: +1 bloco. ","")&IF(AND(ISNUMBER(J16),J16<0.6),"Português abaixo de 60%: +1 bloco. ","")&IF(AND(ISNUMBER(K16),K16<0.6),"Direito abaixo de 60%: +1 bloco. ","")&IF(AND(G16>0,G16<0.8*F16),"Questões abaixo da meta. ","")))
A17: 11 | B17: 11/01–17/01/27 | C17: 10 | D17: =SUMIFS('Registro diário'!$F$6:$F$504,'Registro diário'!$B$6:$B$504,A17)/60 -> 0 | E17: =IF(D17=0,"",D17/C17) | F17: 70 | G17: =SUMIFS('Registro diário'!$G$6:$G$504,'Registro diário'!$B$6:$B$504,A17) -> 0 | H17: =IF(G17=0,"",SUMIFS('Registro diário'!$H$6:$H$504,'Registro diário'!$B$6:$B$504,A17)/G17) | I17: =IF(SUMIFS('Registro diário'!$G$6:$G$504,'Registro diário'!$B$6:$B$504,$A17,'Registro diário'!$C$6:$C$504,"Medicina Legal")=0,"",SUMIFS('Registro diário'!$H$6:$H$504,'Registro diário'!$B$6:$B$504,$A17,'Registro diário'!$C$6:$C$504,"Medicina Legal")/SUMIFS('Registro diário'!$G$6:$G$504,'Registro diário'!$B$6:$B$504,$A17,'Registro diário'!$C$6:$C$504,"Medicina Legal")) | J17: =IF(SUMIFS('Registro diário'!$G$6:$G$504,'Registro diário'!$B$6:$B$504,$A17,'Registro diário'!$C$6:$C$504,"Português")=0,"",SUMIFS('Registro diário'!$H$6:$H$504,'Registro diário'!$B$6:$B$504,$A17,'Registro diário'!$C$6:$C$504,"Português")/SUMIFS('Registro diário'!$G$6:$G$504,'Registro diário'!$B$6:$B$504,$A17,'Registro diário'!$C$6:$C$504,"Português")) | K17: =IF(SUMIFS('Registro diário'!$G$6:$G$504,'Registro diário'!$B$6:$B$504,$A17,'Registro diário'!$C$6:$C$504,"Direito")=0,"",SUMIFS('Registro diário'!$H$6:$H$504,'Registro diário'!$B$6:$B$504,$A17,'Registro diário'!$C$6:$C$504,"Direito")/SUMIFS('Registro diário'!$G$6:$G$504,'Registro diário'!$B$6:$B$504,$A17,'Registro diário'!$C$6:$C$504,"Direito")) | L17: =COUNTIF(Edital!$D$7:$D$57,"<="&A17)/51 -> 0.58823529 | M17: =IF(D17=0,"",IF(IF(AND(ISNUMBER(E17),E17<0.8),"Horas abaixo de 80%. ","")&IF(AND(ISNUMBER(I17),I17<0.6),"ML abaixo de 60%: +1 bloco. ","")&IF(AND(ISNUMBER(J17),J17<0.6),"Português abaixo de 60%: +1 bloco. ","")&IF(AND(ISNUMBER(K17),K17<0.6),"Direito abaixo de 60%: +1 bloco. ","")&IF(AND(G17>0,G17<0.8*F17),"Questões abaixo da meta. ","")="","Dentro do plano",IF(AND(ISNUMBER(E17),E17<0.8),"Horas abaixo de 80%. ","")&IF(AND(ISNUMBER(I17),I17<0.6),"ML abaixo de 60%: +1 bloco. ","")&IF(AND(ISNUMBER(J17),J17<0.6),"Português abaixo de 60%: +1 bloco. ","")&IF(AND(ISNUMBER(K17),K17<0.6),"Direito abaixo de 60%: +1 bloco. ","")&IF(AND(G17>0,G17<0.8*F17),"Questões abaixo da meta. ","")))
A18: 12 | B18: 18/01–24/01/27 | C18: 10 | D18: =SUMIFS('Registro diário'!$F$6:$F$504,'Registro diário'!$B$6:$B$504,A18)/60 -> 0 | E18: =IF(D18=0,"",D18/C18) | F18: 70 | G18: =SUMIFS('Registro diário'!$G$6:$G$504,'Registro diário'!$B$6:$B$504,A18) -> 0 | H18: =IF(G18=0,"",SUMIFS('Registro diário'!$H$6:$H$504,'Registro diário'!$B$6:$B$504,A18)/G18) | I18: =IF(SUMIFS('Registro diário'!$G$6:$G$504,'Registro diário'!$B$6:$B$504,$A18,'Registro diário'!$C$6:$C$504,"Medicina Legal")=0,"",SUMIFS('Registro diário'!$H$6:$H$504,'Registro diário'!$B$6:$B$504,$A18,'Registro diário'!$C$6:$C$504,"Medicina Legal")/SUMIFS('Registro diário'!$G$6:$G$504,'Registro diário'!$B$6:$B$504,$A18,'Registro diário'!$C$6:$C$504,"Medicina Legal")) | J18: =IF(SUMIFS('Registro diário'!$G$6:$G$504,'Registro diário'!$B$6:$B$504,$A18,'Registro diário'!$C$6:$C$504,"Português")=0,"",SUMIFS('Registro diário'!$H$6:$H$504,'Registro diário'!$B$6:$B$504,$A18,'Registro diário'!$C$6:$C$504,"Português")/SUMIFS('Registro diário'!$G$6:$G$504,'Registro diário'!$B$6:$B$504,$A18,'Registro diário'!$C$6:$C$504,"Português")) | K18: =IF(SUMIFS('Registro diário'!$G$6:$G$504,'Registro diário'!$B$6:$B$504,$A18,'Registro diário'!$C$6:$C$504,"Direito")=0,"",SUMIFS('Registro diário'!$H$6:$H$504,'Registro diário'!$B$6:$B$504,$A18,'Registro diário'!$C$6:$C$504,"Direito")/SUMIFS('Registro diário'!$G$6:$G$504,'Registro diário'!$B$6:$B$504,$A18,'Registro diário'!$C$6:$C$504,"Direito")) | L18: =COUNTIF(Edital!$D$7:$D$57,"<="&A18)/51 -> 0.64705882 | M18: =IF(D18=0,"",IF(IF(AND(ISNUMBER(E18),E18<0.8),"Horas abaixo de 80%. ","")&IF(AND(ISNUMBER(I18),I18<0.6),"ML abaixo de 60%: +1 bloco. ","")&IF(AND(ISNUMBER(J18),J18<0.6),"Português abaixo de 60%: +1 bloco. ","")&IF(AND(ISNUMBER(K18),K18<0.6),"Direito abaixo de 60%: +1 bloco. ","")&IF(AND(G18>0,G18<0.8*F18),"Questões abaixo da meta. ","")="","Dentro do plano",IF(AND(ISNUMBER(E18),E18<0.8),"Horas abaixo de 80%. ","")&IF(AND(ISNUMBER(I18),I18<0.6),"ML abaixo de 60%: +1 bloco. ","")&IF(AND(ISNUMBER(J18),J18<0.6),"Português abaixo de 60%: +1 bloco. ","")&IF(AND(ISNUMBER(K18),K18<0.6),"Direito abaixo de 60%: +1 bloco. ","")&IF(AND(G18>0,G18<0.8*F18),"Questões abaixo da meta. ","")))
... A32: 26 | B32: 26/04–02/05/27 | C32: 6 | D32: =SUMIFS('Registro diário'!$F$6:$F$504,'Registro diário'!$B$6:$B$504,A32)/60 -> 0 | E32: =IF(D32=0,"",D32/C32) | F32: 40 | G32: =SUMIFS('Registro diário'!$G$6:$G$504,'Registro diário'!$B$6:$B$504,A32) -> 0 | H32: =IF(G32=0,"",SUMIFS('Registro diário'!$H$6:$H$504,'Registro diário'!$B$6:$B$504,A32)/G32) | I32: =IF(SUMIFS('Registro diário'!$G$6:$G$504,'Registro diário'!$B$6:$B$504,$A32,'Registro diário'!$C$6:$C$504,"Medicina Legal")=0,"",SUMIFS('Registro diário'!$H$6:$H$504,'Registro diário'!$B$6:$B$504,$A32,'Registro diário'!$C$6:$C$504,"Medicina Legal")/SUMIFS('Registro diário'!$G$6:$G$504,'Registro diário'!$B$6:$B$504,$A32,'Registro diário'!$C$6:$C$504,"Medicina Legal")) | J32: =IF(SUMIFS('Registro diário'!$G$6:$G$504,'Registro diário'!$B$6:$B$504,$A32,'Registro diário'!$C$6:$C$504,"Português")=0,"",SUMIFS('Registro diário'!$H$6:$H$504,'Registro diário'!$B$6:$B$504,$A32,'Registro diário'!$C$6:$C$504,"Português")/SUMIFS('Registro diário'!$G$6:$G$504,'Registro diário'!$B$6:$B$504,$A32,'Registro diário'!$C$6:$C$504,"Português")) | K32: =IF(SUMIFS('Registro diário'!$G$6:$G$504,'Registro diário'!$B$6:$B$504,$A32,'Registro diário'!$C$6:$C$504,"Direito")=0,"",SUMIFS('Registro diário'!$H$6:$H$504,'Registro diário'!$B$6:$B$504,$A32,'Registro diário'!$C$6:$C$504,"Direito")/SUMIFS('Registro diário'!$G$6:$G$504,'Registro diário'!$B$6:$B$504,$A32,'Registro diário'!$C$6:$C$504,"Direito")) | L32: =COUNTIF(Edital!$D$7:$D$57,"<="&A32)/51 -> 1 | M32: =IF(D32=0,"",IF(IF(AND(ISNUMBER(E32),E32<0.8),"Horas abaixo de 80%. ","")&IF(AND(ISNUMBER(I32),I32<0.6),"ML abaixo de 60%: +1 bloco. ","")&IF(AND(ISNUMBER(J32),J32<0.6),"Português abaixo de 60%: +1 bloco. ","")&IF(AND(ISNUMBER(K32),K32<0.6),"Direito abaixo de 60%: +1 bloco. ","")&IF(AND(G32>0,G32<0.8*F32),"Questões abaixo da meta. ","")="","Dentro do plano",IF(AND(ISNUMBER(E32),E32<0.8),"Horas abaixo de 80%. ","")&IF(AND(ISNUMBER(I32),I32<0.6),"ML abaixo de 60%: +1 bloco. ","")&IF(AND(ISNUMBER(J32),J32<0.6),"Português abaixo de 60%: +1 bloco. ","")&IF(AND(ISNUMBER(K32),K32<0.6),"Direito abaixo de 60%: +1 bloco. ","")&IF(AND(G32>0,G32<0.8*F32),"Questões abaixo da meta. ","")))

Sheet Caderno de erros
A1: Caderno de erros
A2: Uma linha por erro (ou acerto no chute). Revise na data indicada e marque Revisado = Sim.
A3: Para revisar hoje | B3: =COUNTIFS(H7:H404,"<="&TODAY(),I7:I404,"<>Sim") -> 0 | C3: Não sabia | D3: =COUNTIF(E7:E404,"Não sabia") -> 0 | E3: Confundi conceitos | F3: =COUNTIF(E7:E404,"Confundi conceitos") -> 0 | G3: Interpretação | H3: =COUNTIF(E7:E404,"Interpretação") -> 0 | I3: Falta de atenção | J3: =COUNTIF(E7:E404,"Falta de atenção") -> 0 | K3: Tempo | L3: =COUNTIF(E7:E404,"Tempo") -> 0
A5: 03/11/2026 (ex.) | B5: Medicina Legal | C5: ML01 | D5: QConcursos nº 123456 | E5: Confundi conceitos | F5: Achei que parecer era o mesmo que relatório | G5: Parecer: opinião sobre perícia já feita, sem exame; relatório (laudo) descreve o exame | H5: 10/11/2026 | I5: Sim
A6: Data | B6: Disciplina | C6: Código do tópico | D6: Questão / fonte | E6: Motivo do erro | F6: O que eu errei | G6: Regra correta (1 linha) | H6: Revisar em | I6: Revisado?
H7: =IF(A7="","",A7+7)
H8: =IF(A8="","",A8+7)
H9: =IF(A9="","",A9+7)
H10: =IF(A10="","",A10+7)
H11: =IF(A11="","",A11+7)
H12: =IF(A12="","",A12+7)
H13: =IF(A13="","",A13+7)
H14: =IF(A14="","",A14+7)
H15: =IF(A15="","",A15+7)
H16: =IF(A16="","",A16+7)
H17: =IF(A17="","",A17+7)
H18: =IF(A18="","",A18+7)
... H404: =IF(A404="","",A404+7)

Sheet Simulados
A1: Simulados
A2: Mínimo do edital: 50% em CADA módulo (ML 25/50 · Port 15/30 · Dir 10/20). Meta de segurança: acima de 70% no geral.
